<mujoco model="aloha_scene">
  <compiler angle="radian" meshdir="assets" texturedir="assets" autolimits="true"/>
  <option cone="elliptic" impratio="10" gravity="0 0 -9.81"/>

  
  <statistic center="0. 0. 1." extent="1.8" meansize="0.05"/>

  <visual>
    <headlight diffuse="0.6 0.6 0.6" ambient="0.3 0.3 0.3" specular="0 0 0"/>
    <rgba haze="0.15 0.25 0.35 1"/>
    <global azimuth="160" elevation="-20" offwidth="720" offheight="1280"/>
    <quality shadowsize="8192"/>
  </visual>

  <asset>
    <!-- table extrusions and frame -->
    <mesh file="extrusion_2040_880.stl"/>
    <mesh file="extrusion_150.stl"/>
    <mesh file="corner_bracket.stl"/>
    <mesh file="extrusion_1220.stl"/>
    <mesh file="extrusion_1000.stl"/>
    <mesh file="angled_extrusion.stl"/>
    <mesh file="extrusion_600.stl"/>
    <mesh file="overhead_mount.stl"/>
    <mesh file="extrusion_2040_1000.stl"/>
    <mesh file="wormseye_mount.stl"/>

    <!-- Table dimensions (length x width x height in meters): 1.21x0.76x0.75 -->
    <mesh file="tablelegs.obj"/>
    <mesh file="tabletop.obj"/>

    <texture type="skybox" builtin="gradient" rgb1="0.3 0.5 0.7" rgb2="0 0 0" width="512" height="3072"/>
    <texture type="2d" name="groundplane" builtin="checker" mark="edge" rgb1="0.2 0.3 0.4" rgb2="0.1 0.2 0.3"
      markrgb="0.8 0.8 0.8" width="300" height="300"/>
    <texture type="2d" file="small_meta_table_diffuse.png"/>
    <material name="groundplane" texture="groundplane" texuniform="true" texrepeat="5 5" reflectance="0.2"/>
    <material name="table" texture="small_meta_table_diffuse"/>
    <material name="metal" rgba="0.517 0.529 0.537 1"/>
    <material name="black" rgba="0.15 0.15 0.15 1"/>
    <mesh file="vx300s_1_base.stl" scale="0.001 0.001 0.001"/>
    <mesh file="vx300s_2_shoulder.stl" scale="0.001 0.001 0.001"/>
    <mesh file="vx300s_3_upper_arm.stl" scale="0.001 0.001 0.001"/>
    <mesh file="vx300s_4_upper_forearm.stl" scale="0.001 0.001 0.001"/>
    <mesh file="vx300s_5_lower_forearm.stl" scale="0.001 0.001 0.001"/>
    <mesh file="vx300s_6_wrist.stl" scale="0.001 0.001 0.001"/>
    <mesh file="d405_solid.stl"/>
  </asset>

  <default>
    <default class="vx300s">
      <joint axis="0 1 0" actuatorfrcrange="-35 35"/>
      <site group="4"/>
      <default class="waist">
        <joint axis="0 0 1" range="-3.14158 3.14158" damping="5.76"/>
        <position ctrlrange="-3.14158 3.14158" kp="43"/>
      </default>
      <default class="shoulder">
        <joint range="-1.85005 1.25664" armature="0.395" frictionloss="2.0" damping="20.0" actuatorfrcrange="-144 144"/>
        <position ctrlrange="-1.85005 1.25664" kp="265"/>
      </default>
      <default class="elbow">
        <joint range="-1.76278 1.6057" armature="0.383" frictionloss="1.15" damping="18.49" actuatorfrcrange="-59 59"/>
        <position ctrlrange="-1.76278 1.6057" kp="227"/>
      </default>
      <default class="forearm_roll">
        <joint axis="1 0 0" range="-3.14158 3.14158" armature="0.14" damping="6.78" actuatorfrcrange="-22 22"/>
        <position ctrlrange="-3.14158 3.14158" kp="78"/>
      </default>
      <default class="wrist_angle">
        <joint range="-1.8675 2.23402" armature="0.008" damping="6.28"/>
        <position ctrlrange="-1.8675 2.23402" kp="37"/>
      </default>
      <default class="wrist_rotate">
        <joint axis="1 0 0" range="-3.14158 3.14158" damping="1.2"/>
        <position ctrlrange="-3.14158 3.14158" kp="10.4"/>
      </default>
      <default class="visual">
        <geom type="mesh" mass="0" group="2" material="black" contype="0" conaffinity="0"/>
      </default>
      <default class="collision">
        <geom group="3" type="mesh" condim="6" friction="1 5e-3 5e-4" solref=".01 1"/>
        <default class="sphere_collision">
          <geom type="sphere" size="0.0006" rgba="1 0 0 1"/>
        </default>
      </default>
    </default>
    <default class="frame">
      <geom group="1" type="mesh" material="black"/>
    </default>
  </default>

  <worldbody>
    
    <light pos="0 0.1 3.25"/>
    
    <geom name="floor" type="box" size="3 3 0.01" material="groundplane" pos="0 0 0" mass="0"/>

    <site name="worldref" pos="1 1 1.75"/>
    <geom mesh="tabletop" material="table" class="visual" pos="0 0 0" quat="1 0 0 1"/>
    <geom mesh="tablelegs" material="table" class="visual" pos="0 0 0" quat="1 0 0 1"/>
    <geom name="table" pos="0 0 0.6491" size="0.61 0.37 0.1" type="box" class="collision"/>
    <camera name="overhead_cam" focal="1.93e-3 1.93e-3" resolution="1280 720" sensorsize="3896e-6 2140e-6"
            pos="0 -0.303794 1.77524" mode="fixed" quat="0.976332 0.216277 0 0"/>
    <camera name="worms_eye_cam" focal="1.93e-3 1.93e-3" resolution="1280 720" sensorsize="3896e-6 2140e-6"
            pos="0 -0.377167 0.7816055" mode="fixed" quat="0.672659 0.739953 0 0"/>
    

    <!-- Adjusted positions for frame elements -->
    <body name="metal_frame">
      <geom class="frame" pos="0.44 -0.361 1.78" quat="0 1 0 1" mesh="extrusion_2040_880"/>
      <geom class="frame" pos="0.44 -0.371 1.36" quat="1 0 -1 0" mesh="extrusion_150"/>
      <geom class="frame" pos="0 -0.303794 1.77524" quat="0 0 0.976296 0.21644" mesh="d405_solid"/>
      <geom class="frame" pos="0.44 -0.383 1.79" quat="0 0 -1 1" mesh="corner_bracket"/>
      <geom class="frame" pos="-0.61 -0.391 0.74" quat="0 -1 0 1" mesh="extrusion_1220"/>
      <geom class="frame" pos="-0.59 -0.371 1.36" quat="0 -1 0 1" mesh="extrusion_150"/>
      <geom class="frame" pos="0.42 -0.383 1.37" quat="1 1 1 -1" mesh="corner_bracket"/>
      <geom class="frame" pos="0 -0.377167 0.7816055" quat="0 0 -0.672367 -0.740218" mesh="d405_solid"/>
      <geom class="frame" pos="0.61 -0.383 1.37" quat="0 0 1 -1" mesh="corner_bracket"/>
      <geom class="frame" pos="-0.43 -0.361 1.77" quat="0 0 0 1" mesh="extrusion_2040_1000"/>
      <geom class="frame" pos="-0.61 -0.383 1.37" quat="1 1 1 -1" mesh="corner_bracket"/>
      <geom class="frame" pos="-0.43 -0.24 0.87" quat="0.923 0.382 0 0" material="metal" mesh="angled_extrusion"/>
      <geom class="frame" pos="-0.59 -0.066 0.76" quat="0 1 0 -1" mesh="extrusion_150"/>
      <geom class="frame" pos="-0.6 -0.371 1.37" quat="0 0 0 -1" mesh="extrusion_600"/>
      <geom class="frame" pos="0.44 -0.631 0.76" quat="1 0 -1 0" mesh="extrusion_150"/>
      <geom class="frame" pos="0 -0.351 1.78" quat="0 0 1 1" mesh="overhead_mount"/>
      <geom class="frame" pos="-0.43 -0.641 0.76" quat="1 1 -1 1" mesh="extrusion_1000"/>
      <geom class="frame" pos="0.6 -0.26 0.87" quat="0.923 0.382 0 0" material="metal" mesh="angled_extrusion"/>
      <geom class="frame" pos="0.44 -0.066 0.76" quat="1 0 -1 0" mesh="extrusion_150"/>
      <geom class="frame" pos="-0.44 -0.383 1.79" quat="1 1 1 -1" mesh="corner_bracket"/>
      <geom class="frame" pos="-0.61 0.369 0.76" quat="0 1 0 -1" mesh="extrusion_1220"/>
      <geom class="frame" pos="0.43 -0.641 0.76" quat="0 0 -1 1" mesh="extrusion_1000"/>
      <geom class="frame" pos="0.6 -0.641 0.76" quat="0 0 -1 1" mesh="extrusion_1000"/>
      <geom class="frame" pos="-0.59 -0.631 0.76" quat="0 1 0 -1" mesh="extrusion_150"/>
      <geom class="frame" pos="-0.42 -0.383 1.37" quat="0 0 -1 1" mesh="corner_bracket"/>
      <geom class="frame" pos="-0.6 -0.641 0.76" quat="0 0 -1 1" mesh="extrusion_1000"/>
      <geom class="frame" pos="0.6 -0.371 1.37" quat="1 0 0 1" mesh="extrusion_600"/>
      <geom class="frame" pos="0.43 -0.24 0.87" quat="0.923 0.382 0 0" material="metal" mesh="angled_extrusion"/>
      <geom class="frame" pos="-0.6 -0.26 0.87" quat="0.923 0.382 0 0" material="metal" mesh="angled_extrusion"/>
      <geom class="frame" pos="0.43 -0.361 1.77" quat="0 0 0 1" mesh="extrusion_2040_1000"/>
      <geom class="frame" pos="0 -0.391 0.74" quat="0 0 0 1" mesh="wormseye_mount"/>
      <light mode="targetbodycom" target="left_gripper_link" pos="-.5 .7 3.25" cutoff="55"/>
      <light mode="targetbodycom" target="right_gripper_link" pos=".5 .7 3.25" cutoff="55"/>
      <camera name="teleoperator_pov" pos="0 -1.354 1.435" xyaxes="1 0 0 0 0.2 .8"/>
      <camera name="collaborator_pov" pos="0 1.5 1.55" xyaxes="-1 0 0 0 -0.2 .8"/>
    </body>

    <body name="center" pos="0 0 0.75">
    </body>

    <body name="left_base_link" childclass="vx300s" pos="-0.469 -0.019 0.75">
      <inertial pos="-0.0534774 -0.000562575 0.0205961" quat="-0.00292324 0.712517 0.00480387 0.701633" mass="0.969034"
        diaginertia="0.0071633 0.00602451 0.00169819"/>
      <geom quat="1 0 0 1" class="visual" mesh="vx300s_1_base"/>
      <geom quat="1 0 0 1" mesh="vx300s_1_base" class="collision"/>
      <body name="left_shoulder_link" pos="0 0 0.079">
        <inertial pos="0.000259233 -3.3552e-06 0.0116129" quat="-0.476119 0.476083 0.52279 0.522826" mass="0.798614"
          diaginertia="0.00120156 0.00113744 0.0009388"/>
        <joint name="left_waist" class="waist"/>
        <geom pos="0 0 -0.003" quat="1 0 0 1" class="visual" mesh="vx300s_2_shoulder"/>
        <geom pos="0 0 -0.003" quat="1 0 0 1" mesh="vx300s_2_shoulder" class="collision"/>
        <body name="left_upper_arm_link" pos="0 0 0.04805">
          <inertial pos="0.0206949 4e-10 0.226459" quat="0 0.0728458 0 0.997343" mass="0.792592"
            diaginertia="0.00911338 0.008925 0.000759317"/>
          <joint name="left_shoulder" class="shoulder" />
          <geom quat="1 0 0 1" class="visual" mesh="vx300s_3_upper_arm"/>
          <geom quat="1 0 0 1" class="collision" mesh="vx300s_3_upper_arm"/>
          <body name="left_upper_forearm_link" pos="0.05955 0 0.3">
            <inertial pos="0.105723 0 0" quat="-0.000621631 0.704724 0.0105292 0.709403" mass="0.322228"
              diaginertia="0.00144107 0.00134228 0.000152047"/>
            <joint name="left_elbow" class="elbow" ref="-1.7"/>
            <geom class="visual" mesh="vx300s_4_upper_forearm"/>
            <geom class="collision" mesh="vx300s_4_upper_forearm"/>
            <body name="left_lower_forearm_link" pos="0.2 0 0">
              <inertial pos="0.0513477 0.00680462 0" quat="-0.702604 -0.0796724 -0.702604 0.0796724" mass="0.414823"
                diaginertia="0.0005911 0.000546493 0.000155707"/>
              <joint name="left_forearm_roll" class="forearm_roll"/>
              <geom quat="0 1 0 0" class="visual" mesh="vx300s_5_lower_forearm"/>
              <geom quat="0 1 0 0" class="collision" mesh="vx300s_5_lower_forearm"/>
              <body name="left_wrist_link" pos="0.1 0 0">
                <inertial pos="0.046743 -7.6652e-06 0.010565" quat="-0.00100191 0.544586 0.0026583 0.8387"
                  mass="0.115395" diaginertia="5.45707e-05 4.63101e-05 4.32692e-05"/>
                <joint name="left_wrist_angle" class="wrist_angle" ref="-1.7"/>
                <geom quat="1 0 0 1" class="visual" mesh="vx300s_6_wrist"/>
                <geom quat="1 0 0 1" class="collision" mesh="vx300s_6_wrist"/>
                <body name="left_gripper_link" pos="0.069744 0 0">
                  <inertial pos="0.0395662 -2.56311e-07 0.00400649" quat="0.62033 0.619916 -0.339682 0.339869"
                    mass="0.251652" diaginertia="0.000689546 0.000650316 0.000468142"/>
                  <joint name="left_wrist_rotate" class="wrist_rotate"/>
                  <site name="left_gripper" pos="0.13 0 -.003" group="5"/>
                  <camera name="wrist_cam_left" pos="0 -0.0824748 -0.0095955" mode="fixed" euler="2.70525955359 0 0"
                          focal="1.93e-3 1.93e-3" resolution="1280 720" sensorsize="3896e-6 2140e-6"/>
                </body>
              </body>
            </body>
          </body>
        </body>
      </body>
    </body>

    <body name="right_base_link" childclass="vx300s" pos="0.469 -0.019 0.75" quat="0 0 0 1">
      <inertial pos="-0.0534774 -0.000562575 0.0205961" quat="-0.00292324 0.712517 0.00480387 0.701633" mass="0.969034"
        diaginertia="0.0071633 0.00602451 0.00169819"/>
      <geom quat="1 0 0 1" class="visual" mesh="vx300s_1_base"/>
      <geom quat="1 0 0 1" mesh="vx300s_1_base" class="collision"/>
      <body name="right_shoulder_link" pos="0 0 0.079">
        <inertial pos="0.000259233 -3.3552e-06 0.0116129" quat="-0.476119 0.476083 0.52279 0.522826" mass="0.798614"
          diaginertia="0.00120156 0.00113744 0.0009388"/>
        <joint name="right_waist" class="waist"/>
        <geom pos="0 0 -0.003" quat="1 0 0 1" class="visual" mesh="vx300s_2_shoulder"/>
        <geom pos="0 0 -0.003" quat="1 0 0 1" mesh="vx300s_2_shoulder" class="collision"/>
        <body name="right_upper_arm_link" pos="0 0 0.04805">
          <inertial pos="0.0206949 4e-10 0.226459" quat="0 0.0728458 0 0.997343" mass="0.792592"
            diaginertia="0.00911338 0.008925 0.000759317"/>
          <joint name="right_shoulder" class="shoulder" ref="-1.7"/>
          <geom quat="1 0 0 1" class="visual" mesh="vx300s_3_upper_arm"/>
          <geom quat="1 0 0 1" class="collision" mesh="vx300s_3_upper_arm"/>
          <body name="right_upper_forearm_link" pos="0.05955 0 0.3">
            <inertial pos="0.105723 0 0" quat="-0.000621631 0.704724 0.0105292 0.709403" mass="0.322228"
              diaginertia="0.00144107 0.00134228 0.000152047"/>
            <joint name="right_elbow" class="elbow"  ref="-1.7"/>
            <geom class="visual" mesh="vx300s_4_upper_forearm"/>
            <geom class="collision" mesh="vx300s_4_upper_forearm"/>
            <body name="right_lower_forearm_link" pos="0.2 0 0">
              <inertial pos="0.0513477 0.00680462 0" quat="-0.702604 -0.0796724 -0.702604 0.0796724" mass="0.414823"
                diaginertia="0.0005911 0.000546493 0.000155707"/>
              <joint name="right_forearm_roll" class="forearm_roll"/>
              <geom quat="0 1 0 0" class="visual" mesh="vx300s_5_lower_forearm"/>
              <geom quat="0 1 0 0" class="collision" mesh="vx300s_5_lower_forearm"/>
              <body name="right_wrist_link" pos="0.1 0 0">
                <inertial pos="0.046743 -7.6652e-06 0.010565" quat="-0.00100191 0.544586 0.0026583 0.8387"
                  mass="0.115395" diaginertia="5.45707e-05 4.63101e-05 4.32692e-05"/>
                <joint name="right_wrist_angle" class="wrist_angle" ref="-1.7"/>
                <geom quat="1 0 0 1" class="visual" mesh="vx300s_6_wrist"/>
                <geom quat="1 0 0 1" class="collision" mesh="vx300s_6_wrist"/>
                <body name="right_gripper_link" pos="0.069744 0 0">
                  <inertial pos="0.0395662 -2.56311e-07 0.00400649" quat="0.62033 0.619916 -0.339682 0.339869"
                    mass="0.251652" diaginertia="0.000689546 0.000650316 0.000468142"/>
                  <joint name="right_wrist_rotate" class="wrist_rotate"/>
                  <site name="right_gripper" pos="0.13 0 -.003" group="5"/>
                  <camera name="wrist_cam_right" pos="0 -0.0824748 -0.0095955" mode="fixed" euler="2.70525955359 0 0"
                          focal="1.93e-3 1.93e-3" resolution="1280 720" sensorsize="3896e-6 2140e-6"/>
                </body>
              </body>
            </body>
          </body>
        </body>
      </body>
    </body>

    <site name="target" pos="0 0 1" size="0.05" rgba="1 1 1 0"/>
    <site name="target2" pos="0 0 1" size="0.05" rgba="1 1 1 0"/>

  </worldbody>

  <contact>
  <exclude body1="left_base_link" body2="left_shoulder_link"/>
  <exclude body1="right_base_link" body2="right_shoulder_link"/>
  </contact>

  <actuator>
    <position name="left_waist" joint="left_waist" ctrlrange="-3.14158 3.14158" kp="43"/>
    <position name="left_shoulder" joint="left_shoulder" ctrlrange="-1.85005 1.25664" kp="265"/>
    <position name="left_elbow" joint="left_elbow" ctrlrange="-1.76278 1.6057" kp="227"/>
    <position name="left_forearm_roll" joint="left_forearm_roll" ctrlrange="-3.14158 3.14158" kp="78"/>
    <position name="left_wrist_angle" joint="left_wrist_angle" ctrlrange="-1.8675 2.23402" kp="37"/>
    <position name="left_wrist_rotate" joint="left_wrist_rotate" ctrlrange="-3.14158 3.14158" kp="10.4"/>
    
    <position name="right_waist" joint="right_waist" ctrlrange="-3.14158 3.14158" kp="43"/>
    <position name="right_shoulder" joint="right_shoulder" ctrlrange="-1.85005 1.25664" kp="265"/>
    <position name="right_elbow" joint="right_elbow" ctrlrange="-1.76278 1.6057" kp="227"/>
    <position name="right_forearm_roll" joint="right_forearm_roll" ctrlrange="-3.14158 3.14158" kp="78"/>
    <position name="right_wrist_angle" joint="right_wrist_angle" ctrlrange="-1.8675 2.23402" kp="37"/>
    <position name="right_wrist_rotate" joint="right_wrist_rotate" ctrlrange="-3.14158 3.14158" kp="10.4"/>
  </actuator>
  
</mujoco>
